Workbook

Sheet Summary
A1: TATTASE TV — playout schedule
A2: Built from TATTASE_8HRS.xlsx. All times are Lagos time (WAT).
A4: Channel start (WAT) | B4: 46295.847
A5: Loop length (included items) | B5: =SUMPRODUCT(--('Running Order'!$B$2:$B$225="Y"),'Running Order'!$E$2:$E$225) -> 0.54017361
A6: Loop restarts at | B6: =B4+B5 -> 46296.387
A7: Loops per 24 hours | B7: =1/B5 -> 1.8512567
A8: Items in running order | B8: =COUNTA('Running Order'!$C$2:$C$225) -> 224
A9: Items included | B9: =COUNTIF('Running Order'!$B$2:$B$225,"Y") -> 224
A10: Source sheet clock (6:00am to last item) | B10: 0.50074074
A11: Real running time vs source sheet clock | B11: =B5-B10-TIME(0,0,10) -> 0.03931713
A14: Type | B14: Items | C14: Running time | D14: Share
A15: Programme | B15: =COUNTIFS('Running Order'!$D$2:$D$225,A15,'Running Order'!$B$2:$B$225,"Y") -> 40 | C15: =SUMIFS('Running Order'!$E$2:$E$225,'Running Order'!$D$2:$D$225,A15,'Running Order'!$B$2:$B$225,"Y") -> 0.44820602 | D15: =IF($B$5=0,0,C15/$B$5) -> 0.82974438
A16: Short | B16: =COUNTIFS('Running Order'!$D$2:$D$225,A16,'Running Order'!$B$2:$B$225,"Y") -> 60 | C16: =SUMIFS('Running Order'!$E$2:$E$225,'Running Order'!$D$2:$D$225,A16,'Running Order'!$B$2:$B$225,"Y") -> 0.046631944 | D16: =IF($B$5=0,0,C16/$B$5) -> 0.086327698
A17: Commercial | B17: =COUNTIFS('Running Order'!$D$2:$D$225,A17,'Running Order'!$B$2:$B$225,"Y") -> 41 | C17: =SUMIFS('Running Order'!$E$2:$E$225,'Running Order'!$D$2:$D$225,A17,'Running Order'!$B$2:$B$225,"Y") -> 0.029108796 | D17: =IF($B$5=0,0,C17/$B$5) -> 0.053887853
A18: Promo | B18: =COUNTIFS('Running Order'!$D$2:$D$225,A18,'Running Order'!$B$2:$B$225,"Y") -> 14 | C18: =SUMIFS('Running Order'!$E$2:$E$225,'Running Order'!$D$2:$D$225,A18,'Running Order'!$B$2:$B$225,"Y") -> 0.01 | D18: =IF($B$5=0,0,C18/$B$5) -> 0.018512567
A19: Sting | B19: =COUNTIFS('Running Order'!$D$2:$D$225,A19,'Running Order'!$B$2:$B$225,"Y") -> 40 | C19: =SUMIFS('Running Order'!$E$2:$E$225,'Running Order'!$D$2:$D$225,A19,'Running Order'!$B$2:$B$225,"Y") -> 0.0029166667 | D19: =IF($B$5=0,0,C19/$B$5) -> 0.0053994986
A20: Montage | B20: =COUNTIFS('Running Order'!$D$2:$D$225,A20,'Running Order'!$B$2:$B$225,"Y") -> 29 | C20: =SUMIFS('Running Order'!$E$2:$E$225,'Running Order'!$D$2:$D$225,A20,'Running Order'!$B$2:$B$225,"Y") -> 0.0033101852 | D20: =IF($B$5=0,0,C20/$B$5) -> 0.0061280024
A21: Total | B21: =SUM(B15:B20) -> 224 | C21: =SUM(C15:C20) -> 0.54017361 | D21: =SUM(D15:D20) -> 1
A23: Commercial minutes per hour | B23: =IF($B$5=0,0,C17/$B$5*60) -> 3.2332712
A24: Type is my best guess from the title and length. Change any row in Running Order and this table updates.
A26: What to know
A27: 1. The source sheet's clock is short. Its times run 6:00am to 6:01pm (12h), but the file durations add up to about 12h 58m.
A28: Rows 47 (10 Foods to Cut Down, repeat, 23m 25s) and 54 (Green Fields Africa Lekki Farms, 24m 03s) were given only seconds; that hides ~47 min.
A29: Channel Engine plays the files back to back, so the durations decide the real times. See "Actual vs sheet" in Running Order.
A30: 2. Because the loop is ~12h 58m, not 12h, programmes will not air at the same clock time each day: each one airs about 1h 56m later than the day before.
A31: To lock it to a 12h grid, trim ~58 min. Example: set Include = N on the second airing of Agro Food Day 1 (#147) and Osetigo Ep 1 (#154); together ~60 min.
A32: 3. Fixes made while reading: one duration typed as 00:38 (h:mm) read as 38 s (#134); one duration with a stray "-" (#34);
A33: times typed "am" in the afternoon read as pm (#142-147); times with both PM and AM read as PM.
A34: 4. The 40 stings (6-8 s) and 29 montages (10 s) are separate files. Very short files can stutter in Channel Engine: test a few,
A35: or join each sting/montage onto the start of the programme that follows it before uploading.
A36: 5. The commercials are paid spots baked into the running order. When server-side ad insertion comes in, these slots become ad breaks.

Sheet Running Order
A1: # | B1: Include (Y/N) | C1: Item | D1: Type | E1: Duration | F1: Start (WAT) | G1: End (WAT) | H1: Sheet time (as typed) | I1: Sheet time (read as) | J1: Actual vs sheet (min) | K1: Bunny HLS URL (fill in) | L1: Notes
A2: 1 | B2: Y | C2: ORIGINAL SHOWS UPDATED | D2: Programme | E2: 0.002962963 | F2: =Summary!$B$4 -> 46295.847 | G2: =F2+IF(B2="Y",E2,0) -> 46295.85 | H2: 6:00AM | I2: 0.25 | J2: =ROUND((TIME(6,0,0)+(F2-Summary!$B$4)-I2)*1440,1) -> 0
A3: 2 | B3: Y | C3: KIVO HOT PEPPER COMMERCIAL | D3: Commercial | E3: 0.00052083333 | F3: =G2 -> 46295.85 | G3: =F3+IF(B3="Y",E3,0) -> 46295.851 | H3: 6:04:16am | I3: 0.25296296 | J3: =ROUND((TIME(6,0,0)+(F3-Summary!$B$4)-I3)*1440,1) -> 0
A4: 3 | B4: Y | C4: COLGATE TOOTHPASTE | D4: Commercial | E4: 0.00034722222 | F4: =G3 -> 46295.851 | G4: =F4+IF(B4="Y",E4,0) -> 46295.851 | H4: 6:05:01am | I4: 0.2534838 | J4: =ROUND((TIME(6,0,0)+(F4-Summary!$B$4)-I4)*1440,1) -> 0
A5: 4 | B5: Y | C5: CHANNEL MONTAGE | D5: Montage | E5: 0.00011574074 | F5: =G4 -> 46295.851 | G5: =F5+IF(B5="Y",E5,0) -> 46295.851 | H5: 6:05:31am | I5: 0.25383102 | J5: =ROUND((TIME(6,0,0)+(F5-Summary!$B$4)-I5)*1440,1) -> 0
A6: 5 | B6: Y | C6: SIX DELICIOUS STEPS OF ENJOYING A PLATE OF INDOMIE | D6: Short | E6: 0.00068287037 | F6: =G5 -> 46295.851 | G6: =F6+IF(B6="Y",E6,0) -> 46295.852 | H6: 6:05:41am | I6: 0.25394676 | J6: =ROUND((TIME(6,0,0)+(F6-Summary!$B$4)-I6)*1440,1) -> 0
A7: 6 | B7: Y | C7: GREEN FIELD AFRICA`COMING SOON | D7: Promo | E7: 0.00039351852 | F7: =G6 -> 46295.852 | G7: =F7+IF(B7="Y",E7,0) -> 46295.852 | H7: 6:06:40am | I7: 0.25462963 | J7: =ROUND((TIME(6,0,0)+(F7-Summary!$B$4)-I7)*1440,1) -> 0
A8: 7 | B8: Y | C8: ADESUA AND VIVA | D8: Commercial | E8: 0.0011458333 | F8: =G7 -> 46295.852 | G8: =F8+IF(B8="Y",E8,0) -> 46295.853 | H8: 6:07:14am | I8: 0.25502315 | J8: =ROUND((TIME(6,0,0)+(F8-Summary!$B$4)-I8)*1440,1) -> 0
A9: 8 | B9: Y | C9: TATTASE TV COFFEE STING | D9: Sting | E9: 9.2592593e-05 | F9: =G8 -> 46295.853 | G9: =F9+IF(B9="Y",E9,0) -> 46295.853 | H9: 6:08:53am | I9: 0.25616898 | J9: =ROUND((TIME(6,0,0)+(F9-Summary!$B$4)-I9)*1440,1) -> 0
A10: 9 | B10: Y | C10: TASTE OF GHANA | D10: Short | E10: 0.00030092593 | F10: =G9 -> 46295.853 | G10: =F10+IF(B10="Y",E10,0) -> 46295.854 | H10: 6:09:02am | I10: 0.25627315 | J10: =ROUND((TIME(6,0,0)+(F10-Summary!$B$4)-I10)*1440,1) -> 0
A11: 10 | B11: Y | C11: BUKAS AND JOINT | D11: Short | E11: 0.0014699074 | F11: =G10 -> 46295.854 | G11: =F11+IF(B11="Y",E11,0) -> 46295.855 | H11: 6:09:28am | I11: 0.25657407 | J11: =ROUND((TIME(6,0,0)+(F11-Summary!$B$4)-I11)*1440,1) -> 0
A12: 11 | B12: Y | C12: Tattasetv sting | D12: Sting | E12: 6.9444444e-05 | F12: =G11 -> 46295.855 | G12: =F12+IF(B12="Y",E12,0) -> 46295.855 | H12: 6:11:35am | I12: 0.25804398 | J12: =ROUND((TIME(6,0,0)+(F12-Summary!$B$4)-I12)*1440,1) -> 0
A13: 12 | B13: Y | C13: 10 FOODS TO CUT DOWN ON FOR A HEALTHY WEIGHT | D13: Programme | E13: 0.016261574 | F13: =G12 -> 46295.855 | G13: =F13+IF(B13="Y",E13,0) -> 46295.872 | H13: 6:11:41am | I13: 0.25811343 | J13: =ROUND((TIME(6,0,0)+(F13-Summary!$B$4)-I13)*1440,1) -> 0
A14: 13 | B14: Y | C14: CLOSE UP FOR TV COMMERCIALS | D14: Commercial | E14: 0.00034722222 | F14: =G13 -> 46295.872 | G14: =F14+IF(B14="Y",E14,0) -> 46295.872 | H14: 6:35:06am | I14: 0.274375 | J14: =ROUND((TIME(6,0,0)+(F14-Summary!$B$4)-I14)*1440,1) -> 0
... A34: 33 | B34: Y | C34: COCACOLA RECIPE | D34: Short | E34: 0.00034722222 | F34: =G33 -> 46295.88 | G34: =F34+IF(B34="Y",E34,0) -> 46295.88 | H34: 6:44:49am | I34: 0.28112269 | J34: =ROUND((TIME(6,0,0)+(F34-Summary!$B$4)-I34)*1440,1) -> 2.5
A35: 34 | B35: Y | C35: URBAN KITCHEN SHOW NEW | D35: Short | E35: 0.00068287037 | F35: =G34 -> 46295.88 | G35: =F35+IF(B35="Y",E35,0) -> 46295.881 | H35: 6:45:19am | I35: 0.28146991 | J35: =ROUND((TIME(6,0,0)+(F35-Summary!$B$4)-I35)*1440,1) -> 2.5 | L35: duration had a stray "-"
A36: 35 | B36: Y | C36: VEGAN DIARIES REAL | D36: Short | E36: 0.00042824074 | F36: =G35 -> 46295.881 | G36: =F36+IF(B36="Y",E36,0) -> 46295.882 | H36: 6:46:18am | I36: 0.28215278 | J36: =ROUND((TIME(6,0,0)+(F36-Summary!$B$4)-I36)*1440,1) -> 2.5
A37: 36 | B37: Y | C37: FOOD MART | D37: Short | E37: 0.00042824074 | F37: =G36 -> 46295.882 | G37: =F37+IF(B37="Y",E37,0) -> 46295.882 | H37: 6:46:55am | I37: 0.28258102 | J37: =ROUND((TIME(6,0,0)+(F37-Summary!$B$4)-I37)*1440,1) -> 2.5
A38: 37 | B38: Y | C38: TATTASE COFFEE STINGS | D38: Sting | E38: 9.2592593e-05 | F38: =G37 -> 46295.882 | G38: =F38+IF(B38="Y",E38,0) -> 46295.882 | H38: 6:47:32am | I38: 0.28300926 | J38: =ROUND((TIME(6,0,0)+(F38-Summary!$B$4)-I38)*1440,1) -> 2.5
A39: 38 | B39: Y | C39: AJINOMOTO EGG SAUCE AND BOILED YAM | D39: Programme | E39: 0.0027430556 | F39: =G38 -> 46295.882 | G39: =F39+IF(B39="Y",E39,0) -> 46295.885 | H39: 6:47:40am | I39: 0.28310185 | J39: =ROUND((TIME(6,0,0)+(F39-Summary!$B$4)-I39)*1440,1) -> 2.5
A40: 39 | B40: Y | C40: Tattasetv sting | D40: Sting | E40: 6.9444444e-05 | F40: =G39 -> 46295.885 | G40: =F40+IF(B40="Y",E40,0) -> 46295.885 | H40: 6:51:37am | I40: 0.28584491 | J40: =ROUND((TIME(6,0,0)+(F40-Summary!$B$4)-I40)*1440,1) -> 2.5
A41: 40 | B41: Y | C41: THE TRUTH ABOUT NETWORK MARKETING NO-ONE TELLS YOU | D41: Programme | E41: 0.0029976852 | F41: =G40 -> 46295.885 | G41: =F41+IF(B41="Y",E41,0) -> 46295.888 | H41: 6:51:43am | I41: 0.28591435 | J41: =ROUND((TIME(6,0,0)+(F41-Summary!$B$4)-I41)*1440,1) -> 2.5
A42: 41 | B42: Y | C42: BOLEFEST X MALTA GUINESS TV | D42: Short | E42: 0.0012962963 | F42: =G41 -> 46295.888 | G42: =F42+IF(B42="Y",E42,0) -> 46295.889 | H42: 6:56:02am | I42: 0.28891204 | J42: =ROUND((TIME(6,0,0)+(F42-Summary!$B$4)-I42)*1440,1) -> 2.5
A43: 42 | B43: Y | C43: BAKERACE TV | D43: Short | E43: 0.0010300926 | F43: =G42 -> 46295.889 | G43: =F43+IF(B43="Y",E43,0) -> 46295.89 | H43: 6:57:53am | I43: 0.29019676 | J43: =ROUND((TIME(6,0,0)+(F43-Summary!$B$4)-I43)*1440,1) -> 2.6
A44: 43 | B44: Y | C44: RECIPE AFRICA | D44: Short | E44: 0.00025462963 | F44: =G43 -> 46295.89 | G44: =F44+IF(B44="Y",E44,0) -> 46295.89 | H44: 6:59:22am | I44: 0.29122685 | J44: =ROUND((TIME(6,0,0)+(F44-Summary!$B$4)-I44)*1440,1) -> 2.6
A45: 44 | B45: Y | C45: CHANNEL MONTAGE | D45: Montage | E45: 0.00011574074 | F45: =G44 -> 46295.89 | G45: =F45+IF(B45="Y",E45,0) -> 46295.891 | H45: 6:59:44am | I45: 0.29148148 | J45: =ROUND((TIME(6,0,0)+(F45-Summary!$B$4)-I45)*1440,1) -> 2.6
A46: 45 | B46: Y | C46: ORAL B COMMERCIAL VIDEO | D46: Commercial | E46: 0.00034722222 | F46: =G45 -> 46295.891 | G46: =F46+IF(B46="Y",E46,0) -> 46295.891 | H46: 6:59:54am | I46: 0.29159722 | J46: =ROUND((TIME(6,0,0)+(F46-Summary!$B$4)-I46)*1440,1) -> 2.6
A47: 46 | B47: Y | C47: CHANNEL MONTAGE | D47: Montage | E47: 0.00011574074 | F47: =G46 -> 46295.891 | G47: =F47+IF(B47="Y",E47,0) -> 46295.891 | H47: 7:00:24am | I47: 0.29194444 | J47: =ROUND((TIME(6,0,0)+(F47-Summary!$B$4)-I47)*1440,1) -> 2.6
A48: 47 | B48: Y | C48: 10 FOODS TO CUT DOWN ON HEALTHY LIVING | D48: Programme | E48: 0.016261574 | F48: =G47 -> 46295.891 | G48: =F48+IF(B48="Y",E48,0) -> 46295.907 | H48: 7:00:34am | I48: 0.29206019 | J48: =ROUND((TIME(6,0,0)+(F48-Summary!$B$4)-I48)*1440,1) -> 2.6 | L48: sheet allows only a few seconds for this item; its real running time pushes everything after it later
A49: 48 | B49: Y | C49: TATTASE TV STING | D49: Sting | E49: 6.9444444e-05 | F49: =G48 -> 46295.907 | G49: =F49+IF(B49="Y",E49,0) -> 46295.907 | H49: 7:00:40am | I49: 0.29212963 | J49: =ROUND((TIME(6,0,0)+(F49-Summary!$B$4)-I49)*1440,1) -> 25.9
A50: 49 | B50: Y | C50: KIVO VIDEO | D50: Commercial | E50: 0.00052083333 | F50: =G49 -> 46295.907 | G50: =F50+IF(B50="Y",E50,0) -> 46295.908 | H50: 7:01:25am | I50: 0.29265046 | J50: =ROUND((TIME(6,0,0)+(F50-Summary!$B$4)-I50)*1440,1) -> 25.2
A51: 50 | B51: Y | C51: NEW AND IMPROVED GINO MAX CHICKEN | D51: Commercial | E51: 0.00052083333 | F51: =G50 -> 46295.908 | G51: =F51+IF(B51="Y",E51,0) -> 46295.908 | H51: 7:02:10am | I51: 0.2931713 | J51: =ROUND((TIME(6,0,0)+(F51-Summary!$B$4)-I51)*1440,1) -> 25.2
A52: 51 | B52: Y | C52: GOLDEN MOM | D52: Commercial | E52: 0.00063657407 | F52: =G51 -> 46295.908 | G52: =F52+IF(B52="Y",E52,0) -> 46295.909 | H52: 7:03:05am | I52: 0.29380787 | J52: =ROUND((TIME(6,0,0)+(F52-Summary!$B$4)-I52)*1440,1) -> 25.1
A53: 52 | B53: Y | C53: FOOD SHOUTOUTS | D53: Short | E53: 0.00090277778 | F53: =G52 -> 46295.909 | G53: =F53+IF(B53="Y",E53,0) -> 46295.91 | H53: 7:04:00am | I53: 0.29444444 | J53: =ROUND((TIME(6,0,0)+(F53-Summary!$B$4)-I53)*1440,1) -> 25.1
A54: 53 | B54: Y | C54: CHANNEL MONTAGE | D54: Montage | E54: 0.00011574074 | F54: =G53 -> 46295.91 | G54: =F54+IF(B54="Y",E54,0) -> 46295.91 | H54: 7:05:18am | I54: 0.29534722 | J54: =ROUND((TIME(6,0,0)+(F54-Summary!$B$4)-I54)*1440,1) -> 25.1
A55: 54 | B55: Y | C55: GREEN FIELDS AFRICA LEKKI FARMS | D55: Programme | E55: 0.016701389 | F55: =G54 -> 46295.91 | G55: =F55+IF(B55="Y",E55,0) -> 46295.927 | H55: 7:05:28am | I55: 0.29546296 | J55: =ROUND((TIME(6,0,0)+(F55-Summary!$B$4)-I55)*1440,1) -> 25.1 | L55: sheet allows only a few seconds for this item; its real running time pushes everything after it later
A56: 55 | B56: Y | C56: TATTSETV COFFE STINGS | D56: Sting | E56: 9.2592593e-05 | F56: =G55 -> 46295.927 | G56: =F56+IF(B56="Y",E56,0) -> 46295.927 | H56: 7:05:31am | I56: 0.29549769 | J56: =ROUND((TIME(6,0,0)+(F56-Summary!$B$4)-I56)*1440,1) -> 49.1
A57: 56 | B57: Y | C57: AMOR AND CUPID | D57: Short | E57: 0.00099537037 | F57: =G56 -> 46295.927 | G57: =F57+IF(B57="Y",E57,0) -> 46295.928 | H57: 7:05:39am | I57: 0.29559028 | J57: =ROUND((TIME(6,0,0)+(F57-Summary!$B$4)-I57)*1440,1) -> 49.1
A58: 57 | B58: Y | C58: KNOR JOLLOF FEST ABUJA | D58: Short | E58: 0.0013888889 | F58: =G57 -> 46295.928 | G58: =F58+IF(B58="Y",E58,0) -> 46295.929 | H58: 7:07:05am | I58: 0.29658565 | J58: =ROUND((TIME(6,0,0)+(F58-Summary!$B$4)-I58)*1440,1) -> 49.1
A59: 58 | B59: Y | C59: OLAM ANIMAL FEEDS BUSINESS | D59: Programme | E59: 0.0050810185 | F59: =G58 -> 46295.929 | G59: =F59+IF(B59="Y",E59,0) -> 46295.934 | H59: 7:09:05am | I59: 0.29797454 | J59: =ROUND((TIME(6,0,0)+(F59-Summary!$B$4)-I59)*1440,1) -> 49.1
...

Sheet 24h Log
A1: Loop | B1: # | C1: Item | D1: Type | E1: Duration | F1: Start (WAT) | G1: End (WAT) | H1: Status | I1: In first 24h?
A2: =INT((ROW()-2)/Summary!$B$8)+1 -> 1 | B2: =MOD(ROW()-2,Summary!$B$8)+1 -> 1 | C2: =INDEX('Running Order'!$C$2:$C$225,B2) -> ORIGINAL SHOWS UPDATED | D2: =INDEX('Running Order'!$D$2:$D$225,B2) -> Programme | E2: =IF(INDEX('Running Order'!$B$2:$B$225,B2)="Y",INDEX('Running Order'!$E$2:$E$225,B2),0) -> 0.002962963 | F2: =(A2-1)*Summary!$B$5+INDEX('Running Order'!$F$2:$F$225,B2) -> 46295.847 | G2: =F2+E2 -> 46295.85 | H2: =IF(INDEX('Running Order'!$B$2:$B$225,B2)="Y","on air","dropped") -> on air | I2: =IF(F2<Summary!$B$4+1,"yes","") -> yes
A3: =INT((ROW()-2)/Summary!$B$8)+1 -> 1 | B3: =MOD(ROW()-2,Summary!$B$8)+1 -> 2 | C3: =INDEX('Running Order'!$C$2:$C$225,B3) -> KIVO HOT PEPPER COMMERCIAL | D3: =INDEX('Running Order'!$D$2:$D$225,B3) -> Commercial | E3: =IF(INDEX('Running Order'!$B$2:$B$225,B3)="Y",INDEX('Running Order'!$E$2:$E$225,B3),0) -> 0.00052083333 | F3: =(A3-1)*Summary!$B$5+INDEX('Running Order'!$F$2:$F$225,B3) -> 46295.85 | G3: =F3+E3 -> 46295.851 | H3: =IF(INDEX('Running Order'!$B$2:$B$225,B3)="Y","on air","dropped") -> on air | I3: =IF(F3<Summary!$B$4+1,"yes","") -> yes
A4: =INT((ROW()-2)/Summary!$B$8)+1 -> 1 | B4: =MOD(ROW()-2,Summary!$B$8)+1 -> 3 | C4: =INDEX('Running Order'!$C$2:$C$225,B4) -> COLGATE TOOTHPASTE | D4: =INDEX('Running Order'!$D$2:$D$225,B4) -> Commercial | E4: =IF(INDEX('Running Order'!$B$2:$B$225,B4)="Y",INDEX('Running Order'!$E$2:$E$225,B4),0) -> 0.00034722222 | F4: =(A4-1)*Summary!$B$5+INDEX('Running Order'!$F$2:$F$225,B4) -> 46295.851 | G4: =F4+E4 -> 46295.851 | H4: =IF(INDEX('Running Order'!$B$2:$B$225,B4)="Y","on air","dropped") -> on air | I4: =IF(F4<Summary!$B$4+1,"yes","") -> yes
A5: =INT((ROW()-2)/Summary!$B$8)+1 -> 1 | B5: =MOD(ROW()-2,Summary!$B$8)+1 -> 4 | C5: =INDEX('Running Order'!$C$2:$C$225,B5) -> CHANNEL MONTAGE | D5: =INDEX('Running Order'!$D$2:$D$225,B5) -> Montage | E5: =IF(INDEX('Running Order'!$B$2:$B$225,B5)="Y",INDEX('Running Order'!$E$2:$E$225,B5),0) -> 0.00011574074 | F5: =(A5-1)*Summary!$B$5+INDEX('Running Order'!$F$2:$F$225,B5) -> 46295.851 | G5: =F5+E5 -> 46295.851 | H5: =IF(INDEX('Running Order'!$B$2:$B$225,B5)="Y","on air","dropped") -> on air | I5: =IF(F5<Summary!$B$4+1,"yes","") -> yes
A6: =INT((ROW()-2)/Summary!$B$8)+1 -> 1 | B6: =MOD(ROW()-2,Summary!$B$8)+1 -> 5 | C6: =INDEX('Running Order'!$C$2:$C$225,B6) -> SIX DELICIOUS STEPS OF ENJOYING A PLATE OF INDOMIE | D6: =INDEX('Running Order'!$D$2:$D$225,B6) -> Short | E6: =IF(INDEX('Running Order'!$B$2:$B$225,B6)="Y",INDEX('Running Order'!$E$2:$E$225,B6),0) -> 0.00068287037 | F6: =(A6-1)*Summary!$B$5+INDEX('Running Order'!$F$2:$F$225,B6) -> 46295.851 | G6: =F6+E6 -> 46295.852 | H6: =IF(INDEX('Running Order'!$B$2:$B$225,B6)="Y","on air","dropped") -> on air | I6: =IF(F6<Summary!$B$4+1,"yes","") -> yes
A7: =INT((ROW()-2)/Summary!$B$8)+1 -> 1 | B7: =MOD(ROW()-2,Summary!$B$8)+1 -> 6 | C7: =INDEX('Running Order'!$C$2:$C$225,B7) -> GREEN FIELD AFRICA`COMING SOON | D7: =INDEX('Running Order'!$D$2:$D$225,B7) -> Promo | E7: =IF(INDEX('Running Order'!$B$2:$B$225,B7)="Y",INDEX('Running Order'!$E$2:$E$225,B7),0) -> 0.00039351852 | F7: =(A7-1)*Summary!$B$5+INDEX('Running Order'!$F$2:$F$225,B7) -> 46295.852 | G7: =F7+E7 -> 46295.852 | H7: =IF(INDEX('Running Order'!$B$2:$B$225,B7)="Y","on air","dropped") -> on air | I7: =IF(F7<Summary!$B$4+1,"yes","") -> yes
A8: =INT((ROW()-2)/Summary!$B$8)+1 -> 1 | B8: =MOD(ROW()-2,Summary!$B$8)+1 -> 7 | C8: =INDEX('Running Order'!$C$2:$C$225,B8) -> ADESUA AND VIVA | D8: =INDEX('Running Order'!$D$2:$D$225,B8) -> Commercial | E8: =IF(INDEX('Running Order'!$B$2:$B$225,B8)="Y",INDEX('Running Order'!$E$2:$E$225,B8),0) -> 0.0011458333 | F8: =(A8-1)*Summary!$B$5+INDEX('Running Order'!$F$2:$F$225,B8) -> 46295.852 | G8: =F8+E8 -> 46295.853 | H8: =IF(INDEX('Running Order'!$B$2:$B$225,B8)="Y","on air","dropped") -> on air | I8: =IF(F8<Summary!$B$4+1,"yes","") -> yes
A9: =INT((ROW()-2)/Summary!$B$8)+1 -> 1 | B9: =MOD(ROW()-2,Summary!$B$8)+1 -> 8 | C9: =INDEX('Running Order'!$C$2:$C$225,B9) -> TATTASE TV COFFEE STING | D9: =INDEX('Running Order'!$D$2:$D$225,B9) -> Sting | E9: =IF(INDEX('Running Order'!$B$2:$B$225,B9)="Y",INDEX('Running Order'!$E$2:$E$225,B9),0) -> 9.2592593e-05 | F9: =(A9-1)*Summary!$B$5+INDEX('Running Order'!$F$2:$F$225,B9) -> 46295.853 | G9: =F9+E9 -> 46295.853 | H9: =IF(INDEX('Running Order'!$B$2:$B$225,B9)="Y","on air","dropped") -> on air | I9: =IF(F9<Summary!$B$4+1,"yes","") -> yes
A10: =INT((ROW()-2)/Summary!$B$8)+1 -> 1 | B10: =MOD(ROW()-2,Summary!$B$8)+1 -> 9 | C10: =INDEX('Running Order'!$C$2:$C$225,B10) -> TASTE OF GHANA | D10: =INDEX('Running Order'!$D$2:$D$225,B10) -> Short | E10: =IF(INDEX('Running Order'!$B$2:$B$225,B10)="Y",INDEX('Running Order'!$E$2:$E$225,B10),0) -> 0.00030092593 | F10: =(A10-1)*Summary!$B$5+INDEX('Running Order'!$F$2:$F$225,B10) -> 46295.853 | G10: =F10+E10 -> 46295.854 | H10: =IF(INDEX('Running Order'!$B$2:$B$225,B10)="Y","on air","dropped") -> on air | I10: =IF(F10<Summary!$B$4+1,"yes","") -> yes
A11: =INT((ROW()-2)/Summary!$B$8)+1 -> 1 | B11: =MOD(ROW()-2,Summary!$B$8)+1 -> 10 | C11: =INDEX('Running Order'!$C$2:$C$225,B11) -> BUKAS AND JOINT | D11: =INDEX('Running Order'!$D$2:$D$225,B11) -> Short | E11: =IF(INDEX('Running Order'!$B$2:$B$225,B11)="Y",INDEX('Running Order'!$E$2:$E$225,B11),0) -> 0.0014699074 | F11: =(A11-1)*Summary!$B$5+INDEX('Running Order'!$F$2:$F$225,B11) -> 46295.854 | G11: =F11+E11 -> 46295.855 | H11: =IF(INDEX('Running Order'!$B$2:$B$225,B11)="Y","on air","dropped") -> on air | I11: =IF(F11<Summary!$B$4+1,"yes","") -> yes
A12: =INT((ROW()-2)/Summary!$B$8)+1 -> 1 | B12: =MOD(ROW()-2,Summary!$B$8)+1 -> 11 | C12: =INDEX('Running Order'!$C$2:$C$225,B12) -> Tattasetv sting | D12: =INDEX('Running Order'!$D$2:$D$225,B12) -> Sting | E12: =IF(INDEX('Running Order'!$B$2:$B$225,B12)="Y",INDEX('Running Order'!$E$2:$E$225,B12),0) -> 6.9444444e-05 | F12: =(A12-1)*Summary!$B$5+INDEX('Running Order'!$F$2:$F$225,B12) -> 46295.855 | G12: =F12+E12 -> 46295.855 | H12: =IF(INDEX('Running Order'!$B$2:$B$225,B12)="Y","on air","dropped") -> on air | I12: =IF(F12<Summary!$B$4+1,"yes","") -> yes
A13: =INT((ROW()-2)/Summary!$B$8)+1 -> 1 | B13: =MOD(ROW()-2,Summary!$B$8)+1 -> 12 | C13: =INDEX('Running Order'!$C$2:$C$225,B13) -> 10 FOODS TO CUT DOWN ON FOR A HEALTHY WEIGHT | D13: =INDEX('Running Order'!$D$2:$D$225,B13) -> Programme | E13: =IF(INDEX('Running Order'!$B$2:$B$225,B13)="Y",INDEX('Running Order'!$E$2:$E$225,B13),0) -> 0.016261574 | F13: =(A13-1)*Summary!$B$5+INDEX('Running Order'!$F$2:$F$225,B13) -> 46295.855 | G13: =F13+E13 -> 46295.872 | H13: =IF(INDEX('Running Order'!$B$2:$B$225,B13)="Y","on air","dropped") -> on air | I13: =IF(F13<Summary!$B$4+1,"yes","") -> yes
... A449: =INT((ROW()-2)/Summary!$B$8)+1 -> 2 | B449: =MOD(ROW()-2,Summary!$B$8)+1 -> 224 | C449: =INDEX('Running Order'!$C$2:$C$225,B449) -> CHANNEL MONTAGE | D449: =INDEX('Running Order'!$D$2:$D$225,B449) -> Montage | E449: =IF(INDEX('Running Order'!$B$2:$B$225,B449)="Y",INDEX('Running Order'!$E$2:$E$225,B449),0) -> 0.00011574074 | F449: =(A449-1)*Summary!$B$5+INDEX('Running Order'!$F$2:$F$225,B449) -> 46296.927 | G449: =F449+E449 -> 46296.928 | H449: =IF(INDEX('Running Order'!$B$2:$B$225,B449)="Y","on air","dropped") -> on air | I449: =IF(F449<Summary!$B$4+1,"yes","")
A451: Two full loops, starting at Summary!B4. Rows after the first 24 hours are greyed out.

Sheet EPG
A1: Slot | B1: Programme | C1: Start (WAT) | D1: Slot ends | E1: Slot length (min) | F1: Running Order #
A2: 1 | B2: ='Running Order'!C2 -> ORIGINAL SHOWS UPDATED | C2: ='Running Order'!F2 -> 46295.847 | D2: =C3 -> 46295.855 | E2: =ROUND((D2-C2)*1440,1) -> 11.7 | F2: ='Running Order'!A2 -> 1
A3: 2 | B3: ='Running Order'!C13 -> 10 FOODS TO CUT DOWN ON FOR A HEALTHY WEIGHT | C3: ='Running Order'!F13 -> 46295.855 | D3: =C4 -> 46295.882 | E3: =ROUND((D3-C3)*1440,1) -> 38.5 | F3: ='Running Order'!A13 -> 12
A4: 3 | B4: ='Running Order'!C39 -> AJINOMOTO EGG SAUCE AND BOILED YAM | C4: ='Running Order'!F39 -> 46295.882 | D4: =C5 -> 46295.885 | E4: =ROUND((D4-C4)*1440,1) -> 4.1 | F4: ='Running Order'!A39 -> 38
A5: 4 | B5: ='Running Order'!C41 -> THE TRUTH ABOUT NETWORK MARKETING NO-ONE TELLS YOU | C5: ='Running Order'!F41 -> 46295.885 | D5: =C6 -> 46295.891 | E5: =ROUND((D5-C5)*1440,1) -> 8.9 | F5: ='Running Order'!A41 -> 40
A6: 5 | B6: ='Running Order'!C48 -> 10 FOODS TO CUT DOWN ON HEALTHY LIVING | C6: ='Running Order'!F48 -> 46295.891 | D6: =C7 -> 46295.91 | E6: =ROUND((D6-C6)*1440,1) -> 27.4 | F6: ='Running Order'!A48 -> 47
A7: 6 | B7: ='Running Order'!C55 -> GREEN FIELDS AFRICA LEKKI FARMS | C7: ='Running Order'!F55 -> 46295.91 | D7: =C8 -> 46295.929 | E7: =ROUND((D7-C7)*1440,1) -> 27.6 | F7: ='Running Order'!A55 -> 54
A8: 7 | B8: ='Running Order'!C59 -> OLAM ANIMAL FEEDS BUSINESS | C8: ='Running Order'!F59 -> 46295.929 | D8: =C9 -> 46295.938 | E8: =ROUND((D8-C8)*1440,1) -> 12.4 | F8: ='Running Order'!A59 -> 58
A9: 8 | B9: ='Running Order'!C68 -> BEST TIMES TO HAVE BREAKFAST, LUNCH & DINNER | C9: ='Running Order'!F68 -> 46295.938 | D9: =C10 -> 46295.956 | E9: =ROUND((D9-C9)*1440,1) -> 26.5 | F9: ='Running Order'!A68 -> 67
A10: 9 | B10: ='Running Order'!C75 -> COOL KIDS CAN COOK | C10: ='Running Order'!F75 -> 46295.956 | D10: =C11 -> 46295.966 | E10: =ROUND((D10-C10)*1440,1) -> 14 | F10: ='Running Order'!A75 -> 74
A11: 10 | B11: ='Running Order'!C84 -> MAGGI OSETIGO EP1 | C11: ='Running Order'!F84 -> 46295.966 | D11: =C12 -> 46295.986 | E11: =ROUND((D11-C11)*1440,1) -> 28.4 | F11: ='Running Order'!A84 -> 83
A12: 11 | B12: ='Running Order'!C88 -> AGRO FOOD DAY 1 | C12: ='Running Order'!F88 -> 46295.986 | D12: =C13 -> 46296.012 | E12: =ROUND((D12-C12)*1440,1) -> 38 | F12: ='Running Order'!A88 -> 87
A13: 12 | B13: ='Running Order'!C99 -> BOLE FESTIVAL DAY ONE | C13: ='Running Order'!F99 -> 46296.012 | D13: =C14 -> 46296.029 | E13: =ROUND((D13-C13)*1440,1) -> 25 | F13: ='Running Order'!A99 -> 98
A14: 13 | B14: ='Running Order'!C100 -> CHEF ETTE | C14: ='Running Order'!F100 -> 46296.029 | D14: =C15 -> 46296.034 | E14: =ROUND((D14-C14)*1440,1) -> 6.9 | F14: ='Running Order'!A100 -> 99
A15: 14 | B15: ='Running Order'!C105 -> Ep 9 - BAKED PLANTAIN AND SCRAMBLED EGG | C15: ='Running Order'!F105 -> 46296.034 | D15: =C16 -> 46296.05 | E15: =ROUND((D15-C15)*1440,1) -> 22.5 | F15: ='Running Order'!A105 -> 104
A16: 15 | B16: ='Running Order'!C114 -> Olam Cocoa Ghana | C16: ='Running Order'!F114 -> 46296.05 | D16: =C17 -> 46296.06 | E16: =ROUND((D16-C16)*1440,1) -> 14.1 | F16: ='Running Order'!A114 -> 113
A17: 16 | B17: ='Running Order'!C121 -> CHEF EHIS FOR TV | C17: ='Running Order'!F121 -> 46296.06 | D17: =C18 -> 46296.08 | E17: =ROUND((D17-C17)*1440,1) -> 30 | F17: ='Running Order'!A121 -> 120
A18: 17 | B18: ='Running Order'!C123 -> Hilda Bacis inspiring NoLimits Story | C18: ='Running Order'!F123 -> 46296.08 | D18: =C19 -> 46296.085 | E18: =ROUND((D18-C18)*1440,1) -> 6.6 | F18: ='Running Order'!A123 -> 122
A19: 18 | B19: ='Running Order'!C126 -> PAPER PACKAGING COMP | C19: ='Running Order'!F126 -> 46296.085 | D19: =C20 -> 46296.091 | E19: =ROUND((D19-C19)*1440,1) -> 9.5 | F19: ='Running Order'!A126 -> 125
A20: 19 | B20: ='Running Order'!C131 -> Abenas Special Ebubuebunu Soup | C20: ='Running Order'!F131 -> 46296.091 | D20: =C21 -> 46296.098 | E20: =ROUND((D20-C20)*1440,1) -> 9.3 | F20: ='Running Order'!A131 -> 130
A21: 20 | B21: ='Running Order'!C137 -> HEN_FULL VIDEO FOR TV FINAL | C21: ='Running Order'!F137 -> 46296.098 | D21: =C22 -> 46296.119 | E21: =ROUND((D21-C21)*1440,1) -> 30.1 | F21: ='Running Order'!A137 -> 136
A22: 21 | B22: ='Running Order'!C142 -> PROPAK FOR TV | C22: ='Running Order'!F142 -> 46296.119 | D22: =C23 -> 46296.144 | E22: =ROUND((D22-C22)*1440,1) -> 36.4 | F22: ='Running Order'!A142 -> 141
A23: 22 | B23: ='Running Order'!C148 -> AGROFOOD DAY 1 | C23: ='Running Order'!F148 -> 46296.144 | D23: =C24 -> 46296.168 | E23: =ROUND((D23-C23)*1440,1) -> 34.2 | F23: ='Running Order'!A148 -> 147
A24: 23 | B24: ='Running Order'!C153 -> ONGA GHANA COOKS SEASON 1 EPISODE 1 | C24: ='Running Order'!F153 -> 46296.168 | D24: =C25 -> 46296.189 | E24: =ROUND((D24-C24)*1440,1) -> 30.1 | F24: ='Running Order'!A153 -> 152
A25: 24 | B25: ='Running Order'!C155 -> OSETIGO EP1 | C25: ='Running Order'!F155 -> 46296.189 | D25: =C26 -> 46296.208 | E25: =ROUND((D25-C25)*1440,1) -> 27.8 | F25: ='Running Order'!A155 -> 154
A26: 25 | B26: ='Running Order'!C157 -> DJINEE AT HEMBADOON | C26: ='Running Order'!F157 -> 46296.208 | D26: =C27 -> 46296.213 | E26: =ROUND((D26-C26)*1440,1) -> 6.5 | F26: ='Running Order'!A157 -> 156
A27: 26 | B27: ='Running Order'!C159 -> PLANTAIN PEOPLE'S PARTY | C27: ='Running Order'!F159 -> 46296.213 | D27: =C28 -> 46296.219 | E27: =ROUND((D27-C27)*1440,1) -> 8.6 | F27: ='Running Order'!A159 -> 158
A28: 27 | B28: ='Running Order'!C161 -> SAUSAGE THREADED SPAGHETTI (LONGER VERSION) | C28: ='Running Order'!F161 -> 46296.219 | D28: =C29 -> 46296.221 | E28: =ROUND((D28-C28)*1440,1) -> 3.4 | F28: ='Running Order'!A161 -> 160
A29: 28 | B29: ='Running Order'!C164 -> SPICES OF LOVE Season1 Episode1 Welcome to the Neighbourhood | C29: ='Running Order'!F164 -> 46296.221 | D29: =C30 -> 46296.228 | E29: =ROUND((D29-C29)*1440,1) -> 10.1 | F29: ='Running Order'!A164 -> 163
A30: 29 | B30: ='Running Order'!C171 -> Fried Rice with Oven Roasted Fish and Moimoi AJINOMOTO 247 Episode11 | C30: ='Running Order'!F171 -> 46296.228 | D30: =C31 -> 46296.235 | E30: =ROUND((D30-C30)*1440,1) -> 9.7 | F30: ='Running Order'!A171 -> 170
A31: 30 | B31: ='Running Order'!C176 -> DRONE 9JA PLASTPRINTPACK | C31: ='Running Order'!F176 -> 46296.235 | D31: =C32 -> 46296.24 | E31: =ROUND((D31-C31)*1440,1) -> 7.8 | F31: ='Running Order'!A176 -> 175
A32: 31 | B32: ='Running Order'!C179 -> Maggi Diaries Season 3 Episode 2 | C32: ='Running Order'!F179 -> 46296.24 | D32: =C33 -> 46296.247 | E32: =ROUND((D32-C32)*1440,1) -> 9.3 | F32: ='Running Order'!A179 -> 178
A33: 32 | B33: ='Running Order'!C182 -> GOODNESS KITCHEN WITH CHEF T | C33: ='Running Order'!F182 -> 46296.247 | D33: =C34 -> 46296.266 | E33: =ROUND((D33-C33)*1440,1) -> 27.7 | F33: ='Running Order'!A182 -> 181
A34: 33 | B34: ='Running Order'!C190 -> DONE STREET FOOD TOUR MR ROLAND (ISLANDER BARBEQUE) | C34: ='Running Order'!F190 -> 46296.266 | D34: =C35 -> 46296.271 | E34: =ROUND((D34-C34)*1440,1) -> 7.7 | F34: ='Running Order'!A190 -> 189
A35: 34 | B35: ='Running Order'!C193 -> MERCYS MENU SEASON 2 EPISODE 1 TAAOOMA COCONUT NOODLES | C35: ='Running Order'!F193 -> 46296.271 | D35: =C36 -> 46296.291 | E35: =ROUND((D35-C35)*1440,1) -> 28.4 | F35: ='Running Order'!A193 -> 192
A36: 35 | B36: ='Running Order'!C201 -> AKWAABA DAY1 | C36: ='Running Order'!F201 -> 46296.291 | D36: =C37 -> 46296.311 | E36: =ROUND((D36-C36)*1440,1) -> 28.7 | F36: ='Running Order'!A201 -> 200
A37: 36 | B37: ='Running Order'!C206 -> KNORR CELEBRITY TAKEOUT SEASON 1 EPISODE 1 | C37: ='Running Order'!F206 -> 46296.311 | D37: =C38 -> 46296.332 | E37: =ROUND((D37-C37)*1440,1) -> 31.3 | F37: ='Running Order'!A206 -> 205
A38: 37 | B38: ='Running Order'!C211 -> BAKE THAT CAKE WITH DRIPPLES - S01E03 _ THE LION KING | C38: ='Running Order'!F211 -> 46296.332 | D38: =C39 -> 46296.35 | E38: =ROUND((D38-C38)*1440,1) -> 24.7 | F38: ='Running Order'!A211 -> 210
A39: 38 | B39: ='Running Order'!C213 -> AJINOMOTO - TOMATO STEW N WHITE RICE | C39: ='Running Order'!F213 -> 46296.35 | D39: =C40 -> 46296.355 | E39: =ROUND((D39-C39)*1440,1) -> 7.2 | F39: ='Running Order'!A213 -> 212
A40: 39 | B40: ='Running Order'!C217 -> Kings Dorm Season 2 Episode 1 | C40: ='Running Order'!F217 -> 46296.355 | D40: =C41 -> 46296.379 | E40: =ROUND((D40-C40)*1440,1) -> 34.8 | F40: ='Running Order'!A217 -> 216
...

Sheet Playlist
A1: Playlist line (copy column A into tattase.txt, remove blank lines)
A2: =IF('Running Order'!B2="Y",IF('Running Order'!K2="","MISSING URL: "&'Running Order'!C2,'Running Order'!K2),"") -> MISSING URL: ORIGINAL SHOWS UPDATED
A3: =IF('Running Order'!B3="Y",IF('Running Order'!K3="","MISSING URL: "&'Running Order'!C3,'Running Order'!K3),"") -> MISSING URL: KIVO HOT PEPPER COMMERCIAL
A4: =IF('Running Order'!B4="Y",IF('Running Order'!K4="","MISSING URL: "&'Running Order'!C4,'Running Order'!K4),"") -> MISSING URL: COLGATE TOOTHPASTE
A5: =IF('Running Order'!B5="Y",IF('Running Order'!K5="","MISSING URL: "&'Running Order'!C5,'Running Order'!K5),"") -> MISSING URL: CHANNEL MONTAGE
A6: =IF('Running Order'!B6="Y",IF('Running Order'!K6="","MISSING URL: "&'Running Order'!C6,'Running Order'!K6),"") -> MISSING URL: SIX DELICIOUS STEPS OF ENJOYING A PLATE OF INDOMIE
A7: =IF('Running Order'!B7="Y",IF('Running Order'!K7="","MISSING URL: "&'Running Order'!C7,'Running Order'!K7),"") -> MISSING URL: GREEN FIELD AFRICA`COMING SOON
A8: =IF('Running Order'!B8="Y",IF('Running Order'!K8="","MISSING URL: "&'Running Order'!C8,'Running Order'!K8),"") -> MISSING URL: ADESUA AND VIVA
A9: =IF('Running Order'!B9="Y",IF('Running Order'!K9="","MISSING URL: "&'Running Order'!C9,'Running Order'!K9),"") -> MISSING URL: TATTASE TV COFFEE STING
A10: =IF('Running Order'!B10="Y",IF('Running Order'!K10="","MISSING URL: "&'Running Order'!C10,'Running Order'!K10),"") -> MISSING URL: TASTE OF GHANA
A11: =IF('Running Order'!B11="Y",IF('Running Order'!K11="","MISSING URL: "&'Running Order'!C11,'Running Order'!K11),"") -> MISSING URL: BUKAS AND JOINT
A12: =IF('Running Order'!B12="Y",IF('Running Order'!K12="","MISSING URL: "&'Running Order'!C12,'Running Order'!K12),"") -> MISSING URL: Tattasetv sting
A13: =IF('Running Order'!B13="Y",IF('Running Order'!K13="","MISSING URL: "&'Running Order'!C13,'Running Order'!K13),"") -> MISSING URL: 10 FOODS TO CUT DOWN ON FOR A HEALTHY WEIGHT
... A225: =IF('Running Order'!B225="Y",IF('Running Order'!K225="","MISSING URL: "&'Running Order'!C225,'Running Order'!K225),"") -> MISSING URL: CHANNEL MONTAGE
A227: Channel Engine Playlist mode reads one HLS URL per line, top to bottom, then loops. Any "MISSING URL" line means that file is not on Bunny yet.
